Workbook

Sheet Products
A1: ProductID | B1: ProductName | C1: Category | D1: UnitSize | E1: UnitType | F1: BaseUnit | G1: Active | H1: Brand
A2: P001 | B2: Milk | C2: Dairy | D2: 1 | E2: Gallon | F2: gallon | G2: TRUE | H2: Generic
A3: P002 | B3: Eggs | C3: Dairy | D3: 12 | E3: Count | F3: egg | G3: TRUE | H3: Generic
A4: P003 | B4: Butter | C4: Dairy | D4: 1 | E4: Pound | F4: lb | G4: TRUE | H4: Generic
A5: P004 | B5: Cheddar Cheese | C5: Dairy | D5: 16 | E5: Ounce | F5: lb | G5: TRUE | H5: Generic
A6: P005 | B6: Greek Yogurt | C6: Dairy | D6: 32 | E6: Ounce | F6: oz | G6: TRUE | H6: Generic
A7: P006 | B7: White Bread | C7: Bakery | D7: 20 | E7: Ounce | F7: oz | G7: TRUE | H7: Generic
A8: P007 | B8: Wheat Bread | C8: Bakery | D8: 20 | E8: Ounce | F8: oz | G8: TRUE | H8: Generic
A9: P008 | B9: Hamburger Buns | C9: Bakery | D9: 8 | E9: Count | F9: count | G9: TRUE | H9: Generic
A10: P009 | B10: Bananas | C10: Produce | D10: 1 | E10: Pound | F10: lb | G10: TRUE | H10: Generic
A11: P010 | B11: Gala Apples | C11: Produce | D11: 1 | E11: Pound | F11: lb | G11: TRUE | H11: Generic
A12: P011 | B12: Avocados | C12: Produce | D12: 1 | E12: Each | F12: each | G12: TRUE | H12: Generic
A13: P012 | B13: Tomatoes | C13: Produce | D13: 1 | E13: Pound | F13: lb | G13: TRUE | H13: Generic
... A31: P030 | B31: Toilet Paper | C31: Household | D31: 12 | E31: Roll | F31: roll | G31: TRUE | H31: Generic

Sheet Stores
A1: StoreID | B1: StoreName | C1: City | D1: State | E1: Active
A2: S001 | B2: Fry's | C2: Chandler | D2: AZ | E2: TRUE
A3: S002 | B3: Walmart | C3: Chandler | D3: AZ | E3: TRUE
A4: S003 | B4: Safeway | C4: Chandler | D4: AZ | E4: TRUE
A5: S004 | B5: Albertsons | C5: Chandler | D5: AZ | E5: TRUE

Sheet Prices
A1: ProductID | B1: StoreID | C1: Price | D1: PackageSize | E1: StartDate | F1: EndDate | G1: PromoType | H1: LoyaltyRequired | I1: Notes | J1: UnitPrice | K1: LastUpdated
A2: P001 | B2: S001 | C2: 3.19 | K2: 2026-06-04
A3: P001 | B3: S002 | C3: 2.58 | K3: 2026-06-04
A4: P001 | B4: S003 | K4: 2026-06-04
A5: P001 | B5: S004 | K5: 2026-06-04
A6: P002 | B6: S001 | C6: 2.09 | K6: 2026-06-04
A7: P002 | B7: S002 | C7: 1.47 | K7: 2026-06-04
A8: P002 | B8: S003 | K8: 2026-06-04
A9: P002 | B9: S004 | K9: 2026-06-04
A10: P003 | B10: S001 | C10: 3.49 | K10: 2026-06-04
A11: P003 | B11: S002 | C11: 3.06 | K11: 2026-06-04
A12: P003 | B12: S003 | K12: 2026-06-04
A13: P003 | B13: S004 | K13: 2026-06-04
A14: P004 | B14: S001 | C14: 3.69 | K14: 2026-06-04
A15: P004 | B15: S002 | C15: 3.58 | K15: 2026-06-04
A16: P004 | B16: S003 | K16: 2026-06-04
A17: P004 | B17: S004 | K17: 2026-06-04
A18: P005 | B18: S001 | C18: 4.99 | K18: 2026-06-04
A19: P005 | B19: S002 | C19: 3.28 | K19: 2026-06-04
A20: P005 | B20: S003 | K20: 2026-06-04
A21: P005 | B21: S004 | K21: 2026-06-04
A22: P006 | B22: S001 | C22: 1.99 | K22: 2026-06-04
A23: P006 | B23: S002 | C23: 2.47 | K23: 2026-06-04
A24: P006 | B24: S003 | K24: 2026-06-04
A25: P006 | B25: S004 | K25: 2026-06-04
A26: P007 | B26: S001 | C26: 1.99 | K26: 2026-06-04
A27: P007 | B27: S002 | C27: 1.97 | K27: 2026-06-04
A28: P007 | B28: S003 | K28: 2026-06-04
A29: P007 | B29: S004 | K29: 2026-06-04
A30: P008 | B30: S001 | K30: 2026-06-04
A31: P008 | B31: S002 | C31: 1.99 | K31: 2026-06-04
A32: P008 | B32: S003 | C32: 1.48 | K32: 2026-06-04
A33: P008 | B33: S004 | K33: 2026-06-04
A34: P009 | B34: S001 | C34: 0.29 | K34: 2026-06-04
A35: P009 | B35: S002 | C35: 0.5 | K35: 2026-06-04
A36: P009 | B36: S003 | K36: 2026-06-04
A37: P009 | B37: S004 | K37: 2026-06-04
A38: P010 | B38: S001 | C38: 3.99 | D38: 3 | J38: =C38/D38 -> 1.33 | K38: 2026-06-04
A39: P010 | B39: S002 | C39: 3.24 | D39: 3 | J39: =C39/D39 -> 1.08 | K39: 2026-06-04
A40: P010 | B40: S003 | D40: 3 | K40: 2026-06-04
...

Sheet Dashboard
A1: CartCompass MVP Dashboard
A3: Metric | B3: Value
A4: Products Compared | B4: 30
A5: Stores Compared | B5: 2
A6: Status | B6: Fry's + Walmart Loaded
A9: Product | B9: Fry's | C9: Walmart | D9: Winner
A10: Milk | B10: 3.19 | C10: 2.58 | D10: Walmart
A11: Eggs | B11: 2.09 | C11: 1.47 | D11: Walmart
A12: Butter | B12: 3.49 | C12: 3.06 | D12: Walmart
A13: Cheddar Cheese | B13: 3.69 | C13: 3.58 | D13: Walmart
A14: White Bread | B14: 1.99 | C14: 2.47 | D14: Fry's

Sheet Dashboard_Auto
A1: CartCompass Automated Dashboard
A3: ProductID | B3: Product | C3: Fry's | D3: Walmart | E3: Winner
A4: P001 | B4: Milk | C4: =SUMIFS(Prices!C:C,Prices!A:A,A4,Prices!B:B,"S001") -> 3.19 | D4: =SUMIFS(Prices!C:C,Prices!A:A,A4,Prices!B:B,"S002") -> 2.58 | E4: =IF(C4=D4,"Tie",IF(C4<D4,"Fry's","Walmart")) -> Walmart
A5: P002 | B5: Eggs | C5: =SUMIFS(Prices!C:C,Prices!A:A,A5,Prices!B:B,"S001") -> 2.09 | D5: =SUMIFS(Prices!C:C,Prices!A:A,A5,Prices!B:B,"S002") -> 1.47 | E5: =IF(C5=D5,"Tie",IF(C5<D5,"Fry's","Walmart")) -> Walmart
A6: P003 | B6: Butter | C6: =SUMIFS(Prices!C:C,Prices!A:A,A6,Prices!B:B,"S001") -> 3.49 | D6: =SUMIFS(Prices!C:C,Prices!A:A,A6,Prices!B:B,"S002") -> 3.06 | E6: =IF(C6=D6,"Tie",IF(C6<D6,"Fry's","Walmart")) -> Walmart
A7: P004 | B7: Cheddar Cheese | C7: =SUMIFS(Prices!C:C,Prices!A:A,A7,Prices!B:B,"S001") -> 3.69 | D7: =SUMIFS(Prices!C:C,Prices!A:A,A7,Prices!B:B,"S002") -> 3.58 | E7: =IF(C7=D7,"Tie",IF(C7<D7,"Fry's","Walmart")) -> Walmart
A8: P005 | B8: Greek Yogurt | C8: =SUMIFS(Prices!C:C,Prices!A:A,A8,Prices!B:B,"S001") -> 4.99 | D8: =SUMIFS(Prices!C:C,Prices!A:A,A8,Prices!B:B,"S002") -> 3.28 | E8: =IF(C8=D8,"Tie",IF(C8<D8,"Fry's","Walmart")) -> Walmart
A9: P006 | B9: White Bread | C9: =SUMIFS(Prices!C:C,Prices!A:A,A9,Prices!B:B,"S001") -> 1.99 | D9: =SUMIFS(Prices!C:C,Prices!A:A,A9,Prices!B:B,"S002") -> 2.47 | E9: =IF(C9=D9,"Tie",IF(C9<D9,"Fry's","Walmart")) -> Fry's
A10: P007 | B10: Wheat Bread | C10: =SUMIFS(Prices!C:C,Prices!A:A,A10,Prices!B:B,"S001") -> 1.99 | D10: =SUMIFS(Prices!C:C,Prices!A:A,A10,Prices!B:B,"S002") -> 1.97 | E10: =IF(C10=D10,"Tie",IF(C10<D10,"Fry's","Walmart")) -> Walmart
A11: P008 | B11: Hamburger Buns | C11: =SUMIFS(Prices!C:C,Prices!A:A,A11,Prices!B:B,"S001") -> 0 | D11: =SUMIFS(Prices!C:C,Prices!A:A,A11,Prices!B:B,"S002") -> 1.99 | E11: =IF(C11=D11,"Tie",IF(C11<D11,"Fry's","Walmart")) -> Fry's
A12: P009 | B12: Bananas | C12: =SUMIFS(Prices!C:C,Prices!A:A,A12,Prices!B:B,"S001") -> 0.29 | D12: =SUMIFS(Prices!C:C,Prices!A:A,A12,Prices!B:B,"S002") -> 0.5 | E12: =IF(C12=D12,"Tie",IF(C12<D12,"Fry's","Walmart")) -> Fry's
A13: P010 | B13: Gala Apples | C13: =SUMIFS(Prices!C:C,Prices!A:A,A13,Prices!B:B,"S001") -> 3.99 | D13: =SUMIFS(Prices!C:C,Prices!A:A,A13,Prices!B:B,"S002") -> 3.24 | E13: =IF(C13=D13,"Tie",IF(C13<D13,"Fry's","Walmart")) -> Walmart
A14: P011 | B14: Avocados | C14: =SUMIFS(Prices!C:C,Prices!A:A,A14,Prices!B:B,"S001") -> 2.5 | D14: =SUMIFS(Prices!C:C,Prices!A:A,A14,Prices!B:B,"S002") -> 0.99 | E14: =IF(C14=D14,"Tie",IF(C14<D14,"Fry's","Walmart")) -> Walmart
A15: P012 | B15: Tomatoes | C15: =SUMIFS(Prices!C:C,Prices!A:A,A15,Prices!B:B,"S001") -> 1.49 | D15: =SUMIFS(Prices!C:C,Prices!A:A,A15,Prices!B:B,"S002") -> 0.97 | E15: =IF(C15=D15,"Tie",IF(C15<D15,"Fry's","Walmart")) -> Walmart
... A33: P030 | B33: Toilet Paper | C33: =SUMIFS(Prices!C:C,Prices!A:A,A33,Prices!B:B,"S001") -> 5 | D33: =SUMIFS(Prices!C:C,Prices!A:A,A33,Prices!B:B,"S002") -> 8.47 | E33: =IF(C33=D33,"Tie",IF(C33<D33,"Fry's","Walmart")) -> Fry's
